01/07/2019 04:57 [ERROR]  Error running application handler <bokeh.application.handlers.script.ScriptHandler object at 0x0000018485E30EF0>: [Errno 2] No such file or directory: 'C:/Users/MichaelBoguslavsky/Tradeteq Dropbox/Tradeteq Team/Clients/#GoFactoring/data analysis/09272018_instruments2.pkl'
File "common.py", line 406, in _get_handle:
f = open(path_or_buf, mode) Traceback (most recent call last):
  File "C:\ProgramData\Anaconda3\lib\site-packages\pandas\io\pickle.py", line 166, in try_read
    return read_wrapper(lambda f: pkl.load(f))
  File "C:\ProgramData\Anaconda3\lib\site-packages\pandas\io\pickle.py", line 147, in read_wrapper
    is_text=False)
  File "C:\ProgramData\Anaconda3\lib\site-packages\pandas\io\common.py", line 406, in _get_handle
    f = open(path_or_buf, mode)
FileNotFoundError: [Errno 2] No such file or directory: 'C:/Users/MichaelBoguslavsky/Tradeteq Dropbox/Tradeteq Team/Clients/#GoFactoring/data analysis/09272018_instruments2.pkl'

During handling of the above exception, another exception occurred:

Traceback (most recent call last):
  File "C:\ProgramData\Anaconda3\lib\site-packages\pandas\io\pickle.py", line 171, in try_read
    lambda f: pc.load(f, encoding=encoding, compat=False))
  File "C:\ProgramData\Anaconda3\lib\site-packages\pandas\io\pickle.py", line 147, in read_wrapper
    is_text=False)
  File "C:\ProgramData\Anaconda3\lib\site-packages\pandas\io\common.py", line 406, in _get_handle
    f = open(path_or_buf, mode)
FileNotFoundError: [Errno 2] No such file or directory: 'C:/Users/MichaelBoguslavsky/Tradeteq Dropbox/Tradeteq Team/Clients/#GoFactoring/data analysis/09272018_instruments2.pkl'

During handling of the above exception, another exception occurred:

Traceback (most recent call last):
  File "C:\ProgramData\Anaconda3\lib\site-packages\pandas\io\pickle.py", line 177, in read_pickle
    return try_read(path)
  File "C:\ProgramData\Anaconda3\lib\site-packages\pandas\io\pickle.py", line 175, in try_read
    lambda f: pc.load(f, encoding=encoding, compat=True))
  File "C:\ProgramData\Anaconda3\lib\site-packages\pandas\io\pickle.py", line 147, in read_wrapper
    is_text=False)
  File "C:\ProgramData\Anaconda3\lib\site-packages\pandas\io\common.py", line 406, in _get_handle
    f = open(path_or_buf, mode)
FileNotFoundError: [Errno 2] No such file or directory: 'C:/Users/MichaelBoguslavsky/Tradeteq Dropbox/Tradeteq Team/Clients/#GoFactoring/data analysis/09272018_instruments2.pkl'

During handling of the above exception, another exception occurred:

Traceback (most recent call last):
  File "C:\ProgramData\Anaconda3\lib\site-packages\pandas\io\pickle.py", line 166, in try_read
    return read_wrapper(lambda f: pkl.load(f))
  File "C:\ProgramData\Anaconda3\lib\site-packages\pandas\io\pickle.py", line 147, in read_wrapper
    is_text=False)
  File "C:\ProgramData\Anaconda3\lib\site-packages\pandas\io\common.py", line 406, in _get_handle
    f = open(path_or_buf, mode)
FileNotFoundError: [Errno 2] No such file or directory: 'C:/Users/MichaelBoguslavsky/Tradeteq Dropbox/Tradeteq Team/Clients/#GoFactoring/data analysis/09272018_instruments2.pkl'

During handling of the above exception, another exception occurred:

Traceback (most recent call last):
  File "C:\ProgramData\Anaconda3\lib\site-packages\pandas\io\pickle.py", line 171, in try_read
    lambda f: pc.load(f, encoding=encoding, compat=False))
  File "C:\ProgramData\Anaconda3\lib\site-packages\pandas\io\pickle.py", line 147, in read_wrapper
    is_text=False)
  File "C:\ProgramData\Anaconda3\lib\site-packages\pandas\io\common.py", line 406, in _get_handle
    f = open(path_or_buf, mode)
FileNotFoundError: [Errno 2] No such file or directory: 'C:/Users/MichaelBoguslavsky/Tradeteq Dropbox/Tradeteq Team/Clients/#GoFactoring/data analysis/09272018_instruments2.pkl'

During handling of the above exception, another exception occurred:

Traceback (most recent call last):
  File "C:\ProgramData\Anaconda3\lib\site-packages\bokeh\application\handlers\code_runner.py", line 180, in run
    exec(self._code, module.__dict__)
  File "C:\Users\david\Dropbox\Work\Data Science\Tradeteq\TTQ_ML_git\network_viz\dashboard\dashboard.py", line 708, in <module>
    df = pd.read_pickle(datafolder + loadprefix+ filename)
  File "C:\ProgramData\Anaconda3\lib\site-packages\pandas\io\pickle.py", line 180, in read_pickle
    return try_read(path, encoding='latin1')
  File "C:\ProgramData\Anaconda3\lib\site-packages\pandas\io\pickle.py", line 175, in try_read
    lambda f: pc.load(f, encoding=encoding, compat=True))
  File "C:\ProgramData\Anaconda3\lib\site-packages\pandas\io\pickle.py", line 147, in read_wrapper
    is_text=False)
  File "C:\ProgramData\Anaconda3\lib\site-packages\pandas\io\common.py", line 406, in _get_handle
    f = open(path_or_buf, mode)
FileNotFoundError: [Errno 2] No such file or directory: 'C:/Users/MichaelBoguslavsky/Tradeteq Dropbox/Tradeteq Team/Clients/#GoFactoring/data analysis/09272018_instruments2.pkl'
 
01/07/2019 04:57 [INFO]  200 GET /dashboard (::1) 7349.01ms
01/07/2019 04:57 [INFO]  200 GET /static/css/bokeh.min.css?v=4c253f78f16b7d5d0c9d1df8062c7f4c (::1) 285.28ms
01/07/2019 04:57 [INFO]  200 GET /static/css/bokeh-tables.min.css?v=86c18b0b1fd30cdbc124e60cb9452e73 (::1) 1.98ms
01/07/2019 04:57 [INFO]  200 GET /static/js/bokeh-gl.min.js?v=70e18d8dcea09947c12764bf85ec76a0 (::1) 2.99ms
01/07/2019 04:57 [INFO]  200 GET /static/css/bokeh-widgets.min.css?v=6f280acb818327130a8c244ce05fd10d (::1) 2.97ms
01/07/2019 04:57 [INFO]  200 GET /static/js/bokeh-widgets.min.js?v=68fceb4be2f3d6410ff2d7704c8b87cf (::1) 15.96ms
01/07/2019 04:57 [INFO]  200 GET /static/js/bokeh-tables.min.js?v=02bdadb2c698bc2855a4d4a69c163821 (::1) 16.96ms
01/07/2019 04:57 [INFO]  200 GET /static/js/bokeh.min.js?v=b343fbb4db791eda9a229febeb303a0b (::1) 27.93ms
01/07/2019 04:57 [INFO]  101 GET /dashboard/ws?bokeh-protocol-version=1.0&bokeh-session-id=xL1yHQ5cHjjpcLvlx8oCRw4ZEr6nqKFijdNG9Kjow2MS (::1) 1.00ms
01/07/2019 04:57 [INFO]  WebSocket connection opened
01/07/2019 04:57 [INFO]  ServerConnection created
01/07/2019 04:57 [WARNING]  404 GET /favicon.ico (::1) 1.00ms
01/07/2019 06:34 [ERROR]  Error running application handler <bokeh.application.handlers.script.ScriptHandler object at 0x000001B6AFEEFF98>: [Errno 2] No such file or directory: 'C:/Users/MichaelBoguslavsky/Tradeteq Dropbox/Tradeteq Team/Clients/#GoFactoring/data analysis/09272018_instruments2.pkl'
File "common.py", line 406, in _get_handle:
f = open(path_or_buf, mode) Traceback (most recent call last):
  File "C:\ProgramData\Anaconda3\lib\site-packages\pandas\io\pickle.py", line 166, in try_read
    return read_wrapper(lambda f: pkl.load(f))
  File "C:\ProgramData\Anaconda3\lib\site-packages\pandas\io\pickle.py", line 147, in read_wrapper
    is_text=False)
  File "C:\ProgramData\Anaconda3\lib\site-packages\pandas\io\common.py", line 406, in _get_handle
    f = open(path_or_buf, mode)
FileNotFoundError: [Errno 2] No such file or directory: 'C:/Users/MichaelBoguslavsky/Tradeteq Dropbox/Tradeteq Team/Clients/#GoFactoring/data analysis/09272018_instruments2.pkl'

During handling of the above exception, another exception occurred:

Traceback (most recent call last):
  File "C:\ProgramData\Anaconda3\lib\site-packages\pandas\io\pickle.py", line 171, in try_read
    lambda f: pc.load(f, encoding=encoding, compat=False))
  File "C:\ProgramData\Anaconda3\lib\site-packages\pandas\io\pickle.py", line 147, in read_wrapper
    is_text=False)
  File "C:\ProgramData\Anaconda3\lib\site-packages\pandas\io\common.py", line 406, in _get_handle
    f = open(path_or_buf, mode)
FileNotFoundError: [Errno 2] No such file or directory: 'C:/Users/MichaelBoguslavsky/Tradeteq Dropbox/Tradeteq Team/Clients/#GoFactoring/data analysis/09272018_instruments2.pkl'

During handling of the above exception, another exception occurred:

Traceback (most recent call last):
  File "C:\ProgramData\Anaconda3\lib\site-packages\pandas\io\pickle.py", line 177, in read_pickle
    return try_read(path)
  File "C:\ProgramData\Anaconda3\lib\site-packages\pandas\io\pickle.py", line 175, in try_read
    lambda f: pc.load(f, encoding=encoding, compat=True))
  File "C:\ProgramData\Anaconda3\lib\site-packages\pandas\io\pickle.py", line 147, in read_wrapper
    is_text=False)
  File "C:\ProgramData\Anaconda3\lib\site-packages\pandas\io\common.py", line 406, in _get_handle
    f = open(path_or_buf, mode)
FileNotFoundError: [Errno 2] No such file or directory: 'C:/Users/MichaelBoguslavsky/Tradeteq Dropbox/Tradeteq Team/Clients/#GoFactoring/data analysis/09272018_instruments2.pkl'

During handling of the above exception, another exception occurred:

Traceback (most recent call last):
  File "C:\ProgramData\Anaconda3\lib\site-packages\pandas\io\pickle.py", line 166, in try_read
    return read_wrapper(lambda f: pkl.load(f))
  File "C:\ProgramData\Anaconda3\lib\site-packages\pandas\io\pickle.py", line 147, in read_wrapper
    is_text=False)
  File "C:\ProgramData\Anaconda3\lib\site-packages\pandas\io\common.py", line 406, in _get_handle
    f = open(path_or_buf, mode)
FileNotFoundError: [Errno 2] No such file or directory: 'C:/Users/MichaelBoguslavsky/Tradeteq Dropbox/Tradeteq Team/Clients/#GoFactoring/data analysis/09272018_instruments2.pkl'

During handling of the above exception, another exception occurred:

Traceback (most recent call last):
  File "C:\ProgramData\Anaconda3\lib\site-packages\pandas\io\pickle.py", line 171, in try_read
    lambda f: pc.load(f, encoding=encoding, compat=False))
  File "C:\ProgramData\Anaconda3\lib\site-packages\pandas\io\pickle.py", line 147, in read_wrapper
    is_text=False)
  File "C:\ProgramData\Anaconda3\lib\site-packages\pandas\io\common.py", line 406, in _get_handle
    f = open(path_or_buf, mode)
FileNotFoundError: [Errno 2] No such file or directory: 'C:/Users/MichaelBoguslavsky/Tradeteq Dropbox/Tradeteq Team/Clients/#GoFactoring/data analysis/09272018_instruments2.pkl'

During handling of the above exception, another exception occurred:

Traceback (most recent call last):
  File "C:\ProgramData\Anaconda3\lib\site-packages\bokeh\application\handlers\code_runner.py", line 180, in run
    exec(self._code, module.__dict__)
  File "C:\Users\david\Dropbox\Work\Data Science\Tradeteq\TTQ_ML_git\network_viz\dashboard\dashboard.py", line 708, in <module>
    df = pd.read_pickle(datafolder + loadprefix+ filename)
  File "C:\ProgramData\Anaconda3\lib\site-packages\pandas\io\pickle.py", line 180, in read_pickle
    return try_read(path, encoding='latin1')
  File "C:\ProgramData\Anaconda3\lib\site-packages\pandas\io\pickle.py", line 175, in try_read
    lambda f: pc.load(f, encoding=encoding, compat=True))
  File "C:\ProgramData\Anaconda3\lib\site-packages\pandas\io\pickle.py", line 147, in read_wrapper
    is_text=False)
  File "C:\ProgramData\Anaconda3\lib\site-packages\pandas\io\common.py", line 406, in _get_handle
    f = open(path_or_buf, mode)
FileNotFoundError: [Errno 2] No such file or directory: 'C:/Users/MichaelBoguslavsky/Tradeteq Dropbox/Tradeteq Team/Clients/#GoFactoring/data analysis/09272018_instruments2.pkl'
 
01/07/2019 06:34 [INFO]  200 GET /dashboard (::1) 4412.81ms
01/07/2019 06:34 [INFO]  101 GET /dashboard/ws?bokeh-protocol-version=1.0&bokeh-session-id=375fi6r87hyjAJ9jc2xyKheUsv2v1BWhFQ0mRwVBHjGs (::1) 1.00ms
01/07/2019 06:34 [INFO]  WebSocket connection opened
01/07/2019 06:34 [INFO]  ServerConnection created
01/07/2019 06:34 [WARNING]  404 GET /favicon.ico (::1) 0.00ms
